{"content": {"suites": {"0": {"status": {"total_pass": 0, "total_skip": 0, "total_xpass": 0, "total_xfail": 0, "total_rerun": 0, "total_fail": 4, "total_error": 0}, "tests": {"0": {"status": "FAIL", "message": "           ConnectionRefusedError: [Errno 111] Connection refused\n       urllib3.exceptions.NewConnectionError: <urllib3.connection.HTTPConnection object at 0x7f2307786280>: Failed to establish a new connection: [Errno 111] Connection refused\n       urllib3.exceptions.MaxRetryError: HTTPConnectionPool(host='127.0.0.1', port=4723): Max retries exceeded with url: /wd/hub/session (Caused by NewConnectionError('<urllib3.connection.HTTPConnection object at 0x7f2307786280>: Failed to establish a new connection: [Errno 111] Connection refused'))\n", "test_name": "test_opsys_p1", "rerun": "0"}, "1": {"status": "FAIL", "message": "           ConnectionRefusedError: [Errno 111] Connection refused\n       urllib3.exceptions.NewConnectionError: <urllib3.connection.HTTPConnection object at 0x7f2305fa60a0>: Failed to establish a new connection: [Errno 111] Connection refused\n       urllib3.exceptions.MaxRetryError: HTTPConnectionPool(host='127.0.0.1', port=4723): Max retries exceeded with url: /wd/hub/session (Caused by NewConnectionError('<urllib3.connection.HTTPConnection object at 0x7f2305fa60a0>: Failed to establish a new connection: [Errno 111] Connection refused'))\n", "test_name": "test_opsys_p2", "rerun": "0"}, "2": {"status": "FAIL", "message": "           ConnectionRefusedError: [Errno 111] Connection refused\n       urllib3.exceptions.NewConnectionError: <urllib3.connection.HTTPConnection object at 0x7f2306349760>: Failed to establish a new connection: [Errno 111] Connection refused\n       urllib3.exceptions.MaxRetryError: HTTPConnectionPool(host='127.0.0.1', port=4723): Max retries exceeded with url: /wd/hub/session (Caused by NewConnectionError('<urllib3.connection.HTTPConnection object at 0x7f2306349760>: Failed to establish a new connection: [Errno 111] Connection refused'))\n", "test_name": "test_opsys_p3", "rerun": "0"}, "3": {"status": "FAIL", "message": "           ConnectionRefusedError: [Errno 111] Connection refused\n       urllib3.exceptions.NewConnectionError: <urllib3.connection.HTTPConnection object at 0x7f2305e5af70>: Failed to establish a new connection: [Errno 111] Connection refused\n       urllib3.exceptions.MaxRetryError: HTTPConnectionPool(host='127.0.0.1', port=4723): Max retries exceeded with url: /wd/hub/session (Caused by NewConnectionError('<urllib3.connection.HTTPConnection object at 0x7f2305e5af70>: Failed to establish a new connection: [Errno 111] Connection refused'))\n", "test_name": "test_opsys_p4", "rerun": "0"}}, "suite_name": "Test_cases.py"}}}, "date": "February 27, 2023", "start_time": 1677465433.78389, "total_suite": 1, "status": "FAIL", "status_list": {"pass": "0", "fail": "4", "skip": "0", "error": "0", "xpass": "0", "xfail": "0", "rerun": "0"}, "total_tests": "4"}